<?xml version="1.0" encoding="utf-8"?>
<!-- This URDF was automatically created by SolidWorks to URDF Exporter! Originally created by Stephen Brawner (brawner@gmail.com) 
     Commit Version: 1.6.0-4-g7f85cfe  Build Version: 1.6.7995.38578
     For more information, please see http://wiki.ros.org/sw_urdf_exporter -->
<robot
  name="manipulator1">
  <link
    name="base_link">
    <inertial>
      <origin
        xyz="-2.22044604925031E-16 -0.00224854905210781 4.44089209850063E-16"
        rpy="0 0 0" />
      <mass
        value="0.139707136084498" />
      <inertia
        ixx="0.000407966760717312"
        ixy="-2.98071223098969E-19"
        ixz="2.52359462446658E-18"
        iyy="0.000362153855961994"
        iyz="6.68817379847048E-18"
        izz="0.000769538503612287" />
    </inertial>
    <visual>
      <origin
        xyz="0 0 0"
        rpy="0 0 0" />
      <geometry>
        <mesh
          filename="package://manipulator1/meshes/base_link.STL" />
      </geometry>
      <material
        name="">
        <color
          rgba="0.96078431372549 0.96078431372549 0.964705882352941 1" />
      </material>
    </visual>
    <collision>
      <origin
        xyz="0 0 0"
        rpy="0 0 0" />
      <geometry>
        <mesh
          filename="package://manipulator1/meshes/base_link.STL" />
      </geometry>
    </collision>
  </link>
  <link
    name="base_plate">
    <inertial>
      <origin
        xyz="-1.22886286372248E-05 0 1.11022302462516E-16"
        rpy="0 0 0" />
      <mass
        value="0.0862820052494155" />
      <inertia
        ixx="0.000123802300064541"
        ixy="1.06663922016303E-19"
        ixz="8.84714563380274E-19"
        iyy="0.000121470538062705"
        iyz="2.03454754632287E-18"
        izz="0.00024491332977204" />
    </inertial>
    <visual>
      <origin
        xyz="0 0 0"
        rpy="0 0 0" />
      <geometry>
        <mesh
          filename="package://manipulator1/meshes/base_plate.STL" />
      </geometry>
      <material
        name="">
        <color
          rgba="0.0980392156862745 0.0980392156862745 0.0980392156862745 1" />
      </material>
    </visual>
    <collision>
      <origin
        xyz="0 0 0"
        rpy="0 0 0" />
      <geometry>
        <mesh
          filename="package://manipulator1/meshes/base_plate.STL" />
      </geometry>
    </collision>
  </link>
  <joint
    name="base_link_j_base_plate"
    type="revolute">
    <origin
      xyz="0 0 0.015"
      rpy="0 0 0" />
    <parent
      link="base_link" />
    <child
      link="base_plate" />
    <axis
      xyz="0 0 -1" />
    <limit
      lower="0"
      upper="6.28"
      effort="500"
      velocity="5" />
  </joint>
  <link
    name="plate_support">
    <inertial>
      <origin
        xyz="4.44089209850063E-16 0.0599999999999996 9.42699875334796E-05"
        rpy="0 0 0" />
      <mass
        value="0.20022424904567" />
      <inertia
        ixx="0.000252771572791514"
        ixy="-4.18218020954489E-19"
        ixz="1.13901000627266E-18"
        iyy="0.000176249764770248"
        iyz="4.112236499079E-18"
        izz="0.00041080341734212" />
    </inertial>
    <visual>
      <origin
        xyz="0 0 0"
        rpy="0 0 0" />
      <geometry>
        <mesh
          filename="package://manipulator1/meshes/plate_support.STL" />
      </geometry>
      <material
        name="">
        <color
          rgba="0.627450980392157 0.627450980392157 0.627450980392157 1" />
      </material>
    </visual>
    <collision>
      <origin
        xyz="0 0 0"
        rpy="0 0 0" />
      <geometry>
        <mesh
          filename="package://manipulator1/meshes/plate_support.STL" />
      </geometry>
    </collision>
  </link>
  <joint
    name="baseplate_j_plate_support"
    type="fixed">
    <origin
      xyz="0.0195 -0.06 0.018179"
      rpy="0 0 0" />
    <parent
      link="base_plate" />
    <child
      link="plate_support" />
    <axis
      xyz="0 0 0" />
  </joint>
  <link
    name="link1_side_plate1">
    <inertial>
      <origin
        xyz="4.44089209850063E-16 0.0150134261644279 0.0554613514893123"
        rpy="0 0 0" />
      <mass
        value="0.0682158367067577" />
      <inertia
        ixx="0.000205387282310402"
        ixy="-5.49279557105901E-19"
        ixz="-9.74556171742922E-19"
        iyy="0.000126772358326724"
        iyz="-1.08018754993082E-08"
        izz="7.88991566366221E-05" />
    </inertial>
    <visual>
      <origin
        xyz="0 0 0"
        rpy="0 0 0" />
      <geometry>
        <mesh
          filename="package://manipulator1/meshes/link1_side_plate1.STL" />
      </geometry>
      <material
        name="">
        <color
          rgba="0.627450980392157 0.627450980392157 0.627450980392157 1" />
      </material>
    </visual>
    <collision>
      <origin
        xyz="0 0 0"
        rpy="0 0 0" />
      <geometry>
        <mesh
          filename="package://manipulator1/meshes/link1_side_plate1.STL" />
      </geometry>
    </collision>
  </link>
  <joint
    name="plate_support_j_sideplate1"
    type="fixed">
    <origin
      xyz="0.0485 0.045 -0.00067857"
      rpy="0 0 0" />
    <parent
      link="plate_support" />
    <child
      link="link1_side_plate1" />
    <axis
      xyz="0 0 0" />
  </joint>
  <link
    name="link1_side_plate12">
    <inertial>
      <origin
        xyz="4.44089209850063E-16 4.44089209850063E-16 0.0310582864617434"
        rpy="0 0 0" />
      <mass
        value="0.0499638320857503" />
      <inertia
        ixx="0.000167600746600551"
        ixy="9.28776659826906E-21"
        ixz="-1.33327816191701E-19"
        iyy="0.000117287241228739"
        iyz="-7.43091486371195E-19"
        izz="5.05216880055031E-05" />
    </inertial>
    <visual>
      <origin
        xyz="0 0 0"
        rpy="0 0 0" />
      <geometry>
        <mesh
          filename="package://manipulator1/meshes/link1_side_plate12.STL" />
      </geometry>
      <material
        name="">
        <color
          rgba="0.627450980392157 0.627450980392157 0.627450980392157 1" />
      </material>
    </visual>
    <collision>
      <origin
        xyz="0 0 0"
        rpy="0 0 0" />
      <geometry>
        <mesh
          filename="package://manipulator1/meshes/link1_side_plate12.STL" />
      </geometry>
    </collision>
  </link>
  <joint
    name="side_plate1_j_side_plate12"
    type="revolute">
    <origin
      xyz="-0.03 0.015 0.08"
      rpy="0 0 0" />
    <parent
      link="link1_side_plate1" />
    <child
      link="link1_side_plate12" />
    <axis
      xyz="1 0 0" />
    <limit
      lower="-1.57"
      upper="1.57"
      effort="500"
      velocity="1" />
  </joint>
  <link
    name="outer_shaft1">
    <inertial>
      <origin
        xyz="-0.00772630874309455 4.44089209850063E-16 -1.11022302462516E-16"
        rpy="0 0 0" />
      <mass
        value="0.509143234421642" />
      <inertia
        ixx="0.00118267157071951"
        ixy="2.14660790273393E-19"
        ixz="-2.13692540459406E-19"
        iyy="0.000788001513669385"
        iyz="-2.07806932890846E-20"
        izz="0.000788001513669385" />
    </inertial>
    <visual>
      <origin
        xyz="0 0 0"
        rpy="0 0 0" />
      <geometry>
        <mesh
          filename="package://manipulator1/meshes/outer_shaft1.STL" />
      </geometry>
      <material
        name="">
        <color
          rgba="0.627450980392157 0.627450980392157 0.627450980392157 1" />
      </material>
    </visual>
    <collision>
      <origin
        xyz="0 0 0"
        rpy="0 0 0" />
      <geometry>
        <mesh
          filename="package://manipulator1/meshes/outer_shaft1.STL" />
      </geometry>
    </collision>
  </link>
  <joint
    name="side_plate12_j_outer_shaft1"
    type="fixed">
    <origin
      xyz="-0.028 0 0"
      rpy="0 0 0" />
    <parent
      link="link1_side_plate12" />
    <child
      link="outer_shaft1" />
    <axis
      xyz="0 0 0" />
  </joint>
  <link
    name="link1_holder">
    <inertial>
      <origin
        xyz="1.54143921293759E-07 -2.52144496393214E-08 -0.005799534584638"
        rpy="0 0 0" />
      <mass
        value="0.0841346188443606" />
      <inertia
        ixx="6.47642859009133E-05"
        ixy="8.23411710931886E-12"
        ixz="-1.08890847202512E-11"
        iyy="5.82653437006155E-05"
        iyz="2.9352113029424E-12"
        izz="0.000103444871427076" />
    </inertial>
    <visual>
      <origin
        xyz="0 0 0"
        rpy="0 0 0" />
      <geometry>
        <mesh
          filename="package://manipulator1/meshes/link1_holder.STL" />
      </geometry>
      <material
        name="">
        <color
          rgba="0.627450980392157 0.627450980392157 0.627450980392157 1" />
      </material>
    </visual>
    <collision>
      <origin
        xyz="0 0 0"
        rpy="0 0 0" />
      <geometry>
        <mesh
          filename="package://manipulator1/meshes/link1_holder.STL" />
      </geometry>
    </collision>
  </link>
  <joint
    name="outer_shaft1_j_link1_holder"
    type="fixed">
    <origin
      xyz="-0.0095001 0 0.076"
      rpy="0 0 0" />
    <parent
      link="outer_shaft1" />
    <child
      link="link1_holder" />
    <axis
      xyz="0 0 0" />
  </joint>
  <link
    name="link1">
    <inertial>
      <origin
        xyz="2.61491217568022E-09 -1.96853406908559E-08 -1.68497195167649E-05"
        rpy="0 0 0" />
      <mass
        value="1.16262072100795" />
      <inertia
        ixx="0.0294764673709808"
        ixy="-7.58278885604543E-09"
        ixz="3.71883808278725E-09"
        iyy="0.0294766181912142"
        iyz="5.34641410549775E-09"
        izz="0.000654113236445879" />
    </inertial>
    <visual>
      <origin
        xyz="0 0 0"
        rpy="0 0 0" />
      <geometry>
        <mesh
          filename="package://manipulator1/meshes/link1.STL" />
      </geometry>
      <material
        name="">
        <color
          rgba="0.0980392156862745 0.0980392156862745 0.0980392156862745 1" />
      </material>
    </visual>
    <collision>
      <origin
        xyz="0 0 0"
        rpy="0 0 0" />
      <geometry>
        <mesh
          filename="package://manipulator1/meshes/link1.STL" />
      </geometry>
    </collision>
  </link>
  <joint
    name="link1_holder_j_link1"
    type="fixed">
    <origin
      xyz="0 0 0.26095"
      rpy="0 0 0" />
    <parent
      link="link1_holder" />
    <child
      link="link1" />
    <axis
      xyz="0 0 0" />
  </joint>
  <link
    name="link1_end_part">
    <inertial>
      <origin
        xyz="-1.74060011626231E-07 1.57060774164108E-07 0.00113323234783302"
        rpy="0 0 0" />
      <mass
        value="0.171901132424438" />
      <inertia
        ixx="0.000147281829071962"
        ixy="-2.17389957093923E-11"
        ixz="-4.90680401859828E-10"
        iyy="0.000200174484694879"
        iyz="1.42730130731353E-09"
        izz="0.000271952693993483" />
    </inertial>
    <visual>
      <origin
        xyz="0 0 0"
        rpy="0 0 0" />
      <geometry>
        <mesh
          filename="package://manipulator1/meshes/link1_end_part.STL" />
      </geometry>
      <material
        name="">
        <color
          rgba="0.627450980392157 0.627450980392157 0.627450980392157 1" />
      </material>
    </visual>
    <collision>
      <origin
        xyz="0 0 0"
        rpy="0 0 0" />
      <geometry>
        <mesh
          filename="package://manipulator1/meshes/link1_end_part.STL" />
      </geometry>
    </collision>
  </link>
  <joint
    name="link1_J_end_part"
    type="fixed">
    <origin
      xyz="0 0 0.24912"
      rpy="0 0 0" />
    <parent
      link="link1" />
    <child
      link="link1_end_part" />
    <axis
      xyz="0 0 0" />
  </joint>
  <link
    name="link2_side_plate11">
    <inertial>
      <origin
        xyz="5.55111512312578E-16 -0.000621912582690287 0.0311549842986414"
        rpy="0 0 0" />
      <mass
        value="0.0528050348230078" />
      <inertia
        ixx="0.000126324772056133"
        ixy="1.50694660718213E-20"
        ixz="-5.54646076186613E-20"
        iyy="9.4701438016944E-05"
        iyz="1.25526676387361E-06"
        izz="3.18433550176184E-05" />
    </inertial>
    <visual>
      <origin
        xyz="0 0 0"
        rpy="0 0 0" />
      <geometry>
        <mesh
          filename="package://manipulator1/meshes/link2_side_plate11.STL" />
      </geometry>
      <material
        name="">
        <color
          rgba="0.627450980392157 0.627450980392157 0.627450980392157 1" />
      </material>
    </visual>
    <collision>
      <origin
        xyz="0 0 0"
        rpy="0 0 0" />
      <geometry>
        <mesh
          filename="package://manipulator1/meshes/link2_side_plate11.STL" />
      </geometry>
    </collision>
  </link>
  <joint
    name="end_part_j_side_plate11"
    type="fixed">
    <origin
      xyz="0.0455 0 0.015927"
      rpy="0 0 0" />
    <parent
      link="link1_end_part" />
    <child
      link="link2_side_plate11" />
    <axis
      xyz="0 0 0" />
  </joint>
  <link
    name="motor_holder">
    <inertial>
      <origin
        xyz="-0.00584650550007593 -2.22044604925031E-16 -4.44089209850063E-16"
        rpy="0 0 0" />
      <mass
        value="0.031956101125965" />
      <inertia
        ixx="1.46272579690827E-05"
        ixy="-3.04094854525027E-22"
        ixz="-1.34311000273746E-20"
        iyy="8.61130071305443E-06"
        iyz="2.56712386368993E-21"
        izz="8.61130071305441E-06" />
    </inertial>
    <visual>
      <origin
        xyz="0 0 0"
        rpy="0 0 0" />
      <geometry>
        <mesh
          filename="package://manipulator1/meshes/motor_holder.STL" />
      </geometry>
      <material
        name="">
        <color
          rgba="0.627450980392157 0.627450980392157 0.627450980392157 1" />
      </material>
    </visual>
    <collision>
      <origin
        xyz="0 0 0"
        rpy="0 0 0" />
      <geometry>
        <mesh
          filename="package://manipulator1/meshes/motor_holder.STL" />
      </geometry>
    </collision>
  </link>
  <joint
    name="link2_side_plate11_j_motor_holder"
    type="fixed">
    <origin
      xyz="-0.00675 -0.0013172 0.065987"
      rpy="0 0 0" />
    <parent
      link="link2_side_plate11" />
    <child
      link="motor_holder" />
    <axis
      xyz="0 0 0" />
  </joint>
  <link
    name="link2_side_plate_12">
    <inertial>
      <origin
        xyz="5.55111512312578E-16 -0.039717131815086 -0.00491984724371952"
        rpy="0 0 0" />
      <mass
        value="0.0287294522350535" />
      <inertia
        ixx="6.13941167735551E-05"
        ixy="3.3920635179007E-20"
        ixz="-6.2467002738095E-21"
        iyy="1.74811605790006E-05"
        iyz="-3.34024586969494E-06"
        izz="4.40326622455339E-05" />
    </inertial>
    <visual>
      <origin
        xyz="0 0 0"
        rpy="0 0 0" />
      <geometry>
        <mesh
          filename="package://manipulator1/meshes/link2_side_plate_12.STL" />
      </geometry>
      <material
        name="">
        <color
          rgba="0.627450980392157 0.627450980392157 0.627450980392157 1" />
      </material>
    </visual>
    <collision>
      <origin
        xyz="0 0 0"
        rpy="0 0 0" />
      <geometry>
        <mesh
          filename="package://manipulator1/meshes/link2_side_plate_12.STL" />
      </geometry>
    </collision>
  </link>
  <joint
    name="motor_holder_j_side_plate_12"
    type="revolute">
    <origin
      xyz="-0.01325 0 0"
      rpy="0 0 0" />
    <parent
      link="motor_holder" />
    <child
      link="link2_side_plate_12" />
    <axis
      xyz="-1 0 0" />
    <limit
      lower="-0.1"
      upper="1.57"
      effort="500"
      velocity="1" />
  </joint>
  <link
    name="outer_shaft2">
    <inertial>
      <origin
        xyz="-0.00185202704146603 -9.2405662460493E-05 6.41056320225264E-05"
        rpy="0 0 0" />
      <mass
        value="0.136055116672961" />
      <inertia
        ixx="0.000202629151935712"
        ixy="-4.64394915785094E-08"
        ixz="3.22327908017919E-08"
        iyy="0.000124866679772093"
        iyz="-5.47298364929438E-06"
        izz="0.000116146064523454" />
    </inertial>
    <visual>
      <origin
        xyz="0 0 0"
        rpy="0 0 0" />
      <geometry>
        <mesh
          filename="package://manipulator1/meshes/outer_shaft2.STL" />
      </geometry>
      <material
        name="">
        <color
          rgba="0.627450980392157 0.627450980392157 0.627450980392157 1" />
      </material>
    </visual>
    <collision>
      <origin
        xyz="0 0 0"
        rpy="0 0 0" />
      <geometry>
        <mesh
          filename="package://manipulator1/meshes/outer_shaft2.STL" />
      </geometry>
    </collision>
  </link>
  <joint
    name="link2_side_plate_j_outer_shaft2"
    type="fixed">
    <origin
      xyz="-0.019951 0 0"
      rpy="0 0 0" />
    <parent
      link="link2_side_plate_12" />
    <child
      link="outer_shaft2" />
    <axis
      xyz="0 0 0" />
  </joint>
  <link
    name="link2_side_plate22">
    <inertial>
      <origin
        xyz="3.33066907387547E-16 -0.0397171318150851 -0.00491984724371974"
        rpy="0 0 0" />
      <mass
        value="0.0287294522350539" />
      <inertia
        ixx="6.13941167735567E-05"
        ixy="1.26868156330376E-21"
        ixz="-3.27976997977857E-20"
        iyy="1.74811605790008E-05"
        iyz="-3.34024586969501E-06"
        izz="4.40326622455353E-05" />
    </inertial>
    <visual>
      <origin
        xyz="0 0 0"
        rpy="0 0 0" />
      <geometry>
        <mesh
          filename="package://manipulator1/meshes/link2_side_plate22.STL" />
      </geometry>
      <material
        name="">
        <color
          rgba="0.627450980392157 0.627450980392157 0.627450980392157 1" />
      </material>
    </visual>
    <collision>
      <origin
        xyz="0 0 0"
        rpy="0 0 0" />
      <geometry>
        <mesh
          filename="package://manipulator1/meshes/link2_side_plate22.STL" />
      </geometry>
    </collision>
  </link>
  <joint
    name="outer_shaft_j_side_plate22"
    type="fixed">
    <origin
      xyz="-0.040049 0 0"
      rpy="0 0 0" />
    <parent
      link="outer_shaft2" />
    <child
      link="link2_side_plate22" />
    <axis
      xyz="0 0 0" />
  </joint>
  <link
    name="link2_holder">
    <inertial>
      <origin
        xyz="2.0619170283398E-06 0.00813205255589899 0.0010073901871086"
        rpy="0 0 0" />
      <mass
        value="0.0930218057872073" />
      <inertia
        ixx="8.39198156970618E-05"
        ixy="-2.6718650837238E-09"
        ixz="-1.77919164025414E-10"
        iyy="9.05510577582414E-05"
        iyz="4.13970788127066E-06"
        izz="5.76455888171896E-05" />
    </inertial>
    <visual>
      <origin
        xyz="0 0 0"
        rpy="0 0 0" />
      <geometry>
        <mesh
          filename="package://manipulator1/meshes/link2_holder.STL" />
      </geometry>
      <material
        name="">
        <color
          rgba="0.627450980392157 0.627450980392157 0.627450980392157 1" />
      </material>
    </visual>
    <collision>
      <origin
        xyz="0 0 0"
        rpy="0 0 0" />
      <geometry>
        <mesh
          filename="package://manipulator1/meshes/link2_holder.STL" />
      </geometry>
    </collision>
  </link>
  <joint
    name="outer_shaft2_J_link2_holder"
    type="fixed">
    <origin
      xyz="-0.01005 -0.070375 -0.0087174"
      rpy="0 0 0" />
    <parent
      link="outer_shaft2" />
    <child
      link="link2_holder" />
    <axis
      xyz="0 0 0" />
  </joint>
  <link
    name="link2">
    <inertial>
      <origin
        xyz="3.32665672786447E-09 -6.24214728683903E-06 -7.73723946023708E-07"
        rpy="0 0 0" />
      <mass
        value="0.738793048590476" />
      <inertia
        ixx="0.0125139162815572"
        ixy="-2.37710463237503E-08"
        ixz="1.91853538131335E-07"
        iyy="0.000453023321934702"
        iyz="-0.00149413526024665"
        izz="0.0123298546752209" />
    </inertial>
    <visual>
      <origin
        xyz="0 0 0"
        rpy="0 0 0" />
      <geometry>
        <mesh
          filename="package://manipulator1/meshes/link2.STL" />
      </geometry>
      <material
        name="">
        <color
          rgba="0.0980392156862745 0.0980392156862745 0.0980392156862745 1" />
      </material>
    </visual>
    <collision>
      <origin
        xyz="0 0 0"
        rpy="0 0 0" />
      <geometry>
        <mesh
          filename="package://manipulator1/meshes/link2.STL" />
      </geometry>
    </collision>
  </link>
  <joint
    name="link2_holder_j_link2"
    type="fixed">
    <origin
      xyz="0 -0.19958 -0.024722"
      rpy="0 0 0" />
    <parent
      link="link2_holder" />
    <child
      link="link2" />
    <axis
      xyz="0 0 0" />
  </joint>
  <link
    name="link3_holder">
    <inertial>
      <origin
        xyz="-1.32817367659577E-07 -0.021143199221398 -0.00254036448894812"
        rpy="0 0 0" />
      <mass
        value="0.188164299848226" />
      <inertia
        ixx="0.000263210682129164"
        ixy="-1.24136411525225E-09"
        ixz="-5.02555876414802E-11"
        iyy="0.000219043978272138"
        iyz="-1.13273894097352E-05"
        izz="0.000310780367033102" />
    </inertial>
    <visual>
      <origin
        xyz="0 0 0"
        rpy="0 0 0" />
      <geometry>
        <mesh
          filename="package://manipulator1/meshes/link3_holder.STL" />
      </geometry>
      <material
        name="">
        <color
          rgba="0.768627450980392 0.207843137254902 0.152941176470588 1" />
      </material>
    </visual>
    <collision>
      <origin
        xyz="0 0 0"
        rpy="0 0 0" />
      <geometry>
        <mesh
          filename="package://manipulator1/meshes/link3_holder.STL" />
      </geometry>
    </collision>
  </link>
  <joint
    name="link2_j_link3_holder"
    type="fixed">
    <origin
      xyz="0 -0.20401 -0.025271"
      rpy="0 0 0" />
    <parent
      link="link2" />
    <child
      link="link3_holder" />
    <axis
      xyz="0 0 0" />
  </joint>
  <link
    name="link3">
    <inertial>
      <origin
        xyz="-0.0170000000959188 -0.0187763595650603 -0.00238682781019572"
        rpy="0 0 0" />
      <mass
        value="0.199449879103002" />
      <inertia
        ixx="0.000445645399692473"
        ixy="3.90013518644957E-12"
        ixz="-3.30846133775281E-11"
        iyy="0.000202127226065979"
        iyz="-3.54670309739077E-05"
        izz="0.000475268786200657" />
    </inertial>
    <visual>
      <origin
        xyz="0 0 0"
        rpy="0 0 0" />
      <geometry>
        <mesh
          filename="package://manipulator1/meshes/link3.STL" />
      </geometry>
      <material
        name="">
        <color
          rgba="1 1 1 0.35" />
      </material>
    </visual>
    <collision>
      <origin
        xyz="0 0 0"
        rpy="0 0 0" />
      <geometry>
        <mesh
          filename="package://manipulator1/meshes/link3.STL" />
      </geometry>
    </collision>
  </link>
  <joint
    name="link3_holder_j_link3"
    type="fixed">
    <origin
      xyz="0.0175 -0.064892 -0.0080382"
      rpy="0 0 0" />
    <parent
      link="link3_holder" />
    <child
      link="link3" />
    <axis
      xyz="0 0 0" />
  </joint>
  <link
    name="bevel1">
    <inertial>
      <origin
        xyz="-0.00377251446524274 1.29785737712496E-10 2.53810306105606E-11"
        rpy="0 0 0" />
      <mass
        value="0.04202578948651" />
      <inertia
        ixx="1.00438476344988E-05"
        ixy="7.48881130729221E-14"
        ixz="2.4373929310945E-14"
        iyy="9.98292053763495E-06"
        iyz="-2.10732752729565E-16"
        izz="9.98292054206863E-06" />
    </inertial>
    <visual>
      <origin
        xyz="0 0 0"
        rpy="0 0 0" />
      <geometry>
        <mesh
          filename="package://manipulator1/meshes/bevel1.STL" />
      </geometry>
      <material
        name="">
        <color
          rgba="1 1 1 0.35" />
      </material>
    </visual>
    <collision>
      <origin
        xyz="0 0 0"
        rpy="0 0 0" />
      <geometry>
        <mesh
          filename="package://manipulator1/meshes/bevel1.STL" />
      </geometry>
    </collision>
  </link>
  <joint
    name="link3_j_bevel1"
    type="revolute">
    <origin
      xyz="0.026096 -0.064131 -0.0081052"
      rpy="0 0 0" />
    <parent
      link="link3" />
    <child
      link="bevel1" />
    <axis
      xyz="-1 0 0" />
    <limit
      lower="0"
      upper="6.28"
      effort="500"
      velocity="1" />
  </joint>
  <link
    name="bevelcoupler">
    <inertial>
      <origin
        xyz="-0.000201386284989447 0.00031529999168578 -0.00362440249815354"
        rpy="0 0 0" />
      <mass
        value="0.0209029839604551" />
      <inertia
        ixx="2.55772080126936E-06"
        ixy="1.1001983416562E-09"
        ixz="-1.33971276273617E-08"
        iyy="3.89976175675072E-06"
        iyz="1.05518303528261E-07"
        izz="3.02571078727523E-06" />
    </inertial>
    <visual>
      <origin
        xyz="0 0 0"
        rpy="0 0 0" />
      <geometry>
        <mesh
          filename="package://manipulator1/meshes/bevelcoupler.STL" />
      </geometry>
      <material
        name="">
        <color
          rgba="1 1 1 0.35" />
      </material>
    </visual>
    <collision>
      <origin
        xyz="0 0 0"
        rpy="0 0 0" />
      <geometry>
        <mesh
          filename="package://manipulator1/meshes/bevelcoupler.STL" />
      </geometry>
    </collision>
  </link>
  <joint
    name="bevel1_j_bevel_coupler"
    type="revolute">   <!-- modification : revolute -> fixed -->
    <origin
      xyz="-0.041897 -0.00059194 0.0068096"
      rpy="0 0 0" />
    <parent
      link="bevel1" />
    <child
      link="bevelcoupler" />
    <axis
      xyz="0 -0.12293 0.99242" />
    <limit
      lower="0"
      upper="6.28"
      effort="20"
      velocity="1" />
  </joint>
  <link
    name="bevel2">
    <inertial>
      <origin
        xyz="0.00377251446525584 3.00959257515387E-12 -1.79158243795996E-10"
        rpy="0 0 0" />
      <mass
        value="0.0420257894865733" />
      <inertia
        ixx="1.00438476345E-05"
        ixy="9.6485284525207E-15"
        ixz="9.55249388963063E-14"
        iyy="9.98292053764471E-06"
        iyz="1.14958570656255E-16"
        izz="9.98292054206497E-06" />
    </inertial>
    <visual>
      <origin
        xyz="0 0 0"
        rpy="0 0 0" />
      <geometry>
        <mesh
          filename="package://manipulator1/meshes/bevel2.STL" />
      </geometry>
      <material
        name="">
        <color
          rgba="1 1 1 0.35" />
      </material>
    </visual>
    <collision>
      <origin
        xyz="0 0 0"
        rpy="0 0 0" />
      <geometry>
        <mesh
          filename="package://manipulator1/meshes/bevel2.STL" />
      </geometry>
    </collision>
  </link>
  <joint
    name="bevel_coupler_j_bevel2"
    type="revolute">    <!-- modification : revolute -> fixed -->
    <origin
      xyz="-0.044295 0.00059194 -0.0068096"
      rpy="0 0 0" />
    <parent
      link="bevelcoupler" />
    <child
      link="bevel2" />
    <axis
      xyz="-1 0 0" />
    <limit
      lower="0"
      upper="6.28"
      effort="20"
      velocity="1" />
  </joint>
  <link
    name="bevel3">
    <inertial>
      <origin
        xyz="-2.57327004149488E-09 0.00344285390081533 0.000426473476989209"
        rpy="0 0 0" />
      <mass
        value="0.0416503672050657" />
      <inertia
        ixx="7.91937238183527E-06"
        ixy="1.16877699647925E-12"
        ixz="1.7608970145984E-13"
        iyy="8.58962156346542E-06"
        iyz="8.30255366944487E-08"
        izz="7.92965699118821E-06" />
    </inertial>
    <visual>
      <origin
        xyz="0 0 0"
        rpy="0 0 0" />
      <geometry>
        <mesh
          filename="package://manipulator1/meshes/bevel3.STL" />
      </geometry>
      <material
        name="">
        <color
          rgba="1 1 1 0.35" />
      </material>
    </visual>
    <collision>
      <origin
        xyz="0 0 0"
        rpy="0 0 0" />
      <geometry>
        <mesh
          filename="package://manipulator1/meshes/bevel3.STL" />
      </geometry>
    </collision>
  </link>
  <joint
    name="bevel_coupler_j_bevel3"
    type="revolute">
    <origin
      xyz="0 0.0057785 -0.047208"
      rpy="1.5708 0 0" />
    <parent
      link="bevelcoupler" />
    <child
      link="bevel3" />
    <axis
      xyz="0 0.99242 0.12293" />
    <limit
      lower="0"
      upper="6.28"
      effort="20"
      velocity="1" />
  </joint>
  <link
    name="gripper_mainbody">
    <inertial>
      <origin
        xyz="-0.00552657904914422 0.00262252623035764 -0.0211699521658091"
        rpy="0 0 0" />
      <mass
        value="0.0880731200826313" />
      <inertia
        ixx="6.0309723672064E-05"
        ixy="-5.24250107092708E-12"
        ixz="3.26827608685038E-11"
        iyy="0.000119926322386792"
        iyz="6.62896108105007E-06"
        izz="6.72329014814773E-05" />
    </inertial>
    <visual>
      <origin
        xyz="0 0 0"
        rpy="0 0 0" />
      <geometry>
        <mesh
          filename="package://manipulator1/meshes/gripper_mainbody.STL" />
      </geometry>
      <material
        name="">
        <color
          rgba="1 1 1 0.35" />
      </material>
    </visual>
    <collision>
      <origin
        xyz="0 0 0"
        rpy="0 0 0" />
      <geometry>
        <mesh
          filename="package://manipulator1/meshes/gripper_mainbody.STL" />
      </geometry>
    </collision>
  </link>
  <joint
    name="bevel3_j_gmainbody"
    type="fixed">
    <origin
      xyz="0.0055265 -0.028356 -0.0035123"
      rpy="-1.5708 0 0" />
    <parent
      link="bevel3" />
    <child
      link="gripper_mainbody" />
    <axis
      xyz="0 0 0" />
  </joint>
  <link
    name="servo">
    <inertial>
      <origin
        xyz="-1.26419985591042E-11 0.019532881802238 0.0125207141649559"
        rpy="0 0 0" />
      <mass
        value="0.0333266321174677" />
      <inertia
        ixx="9.05626657783332E-06"
        ixy="5.91598220324226E-15"
        ixz="-8.29256628787803E-15"
        iyy="5.94795141838003E-06"
        iyz="1.1238930919987E-07"
        izz="5.42992484860492E-06" />
    </inertial>
    <visual>
      <origin
        xyz="0 0 0"
        rpy="0 0 0" />
      <geometry>
        <mesh
          filename="package://manipulator1/meshes/servo.STL" />
      </geometry>
      <material
        name="">
        <color
          rgba="0.792156862745098 0.819607843137255 0.933333333333333 1" />
      </material>
    </visual>
    <collision>
      <origin
        xyz="0 0 0"
        rpy="0 0 0" />
      <geometry>
        <mesh
          filename="package://manipulator1/meshes/servo.STL" />
      </geometry>
    </collision>
  </link>
  <joint
    name="gripper_j_servo"
    type="fixed">
    <origin
      xyz="-0.0055262 -0.0073467 -0.033526"
      rpy="0 0 0" />
    <parent
      link="gripper_mainbody" />
    <child
      link="servo" />
    <axis
      xyz="0 0 0" />
  </joint>
  <link
    name="gl1">
    <inertial>
      <origin
        xyz="-2.21968887714752E-10 -2.16537898722891E-11 1.74806613628675E-10"
        rpy="0 0 0" />
      <mass
        value="0.00217874597756915" />
      <inertia
        ixx="2.1028330117138E-07"
        ixy="1.77740721143962E-08"
        ixz="-1.43487212120176E-07"
        iyy="3.40979174950198E-07"
        iyz="2.45470656712739E-08"
        izz="1.45855378527706E-07" />
    </inertial>
    <visual>
      <origin
        xyz="0 0 0"
        rpy="0 0 0" />
      <geometry>
        <mesh
          filename="package://manipulator1/meshes/gl1.STL" />
      </geometry>
      <material
        name="">
        <color
          rgba="1 1 1 0.35" />
      </material>
    </visual>
    <collision>
      <origin
        xyz="0 0 0"
        rpy="0 0 0" />
      <geometry>
        <mesh
          filename="package://manipulator1/meshes/gl1.STL" />
      </geometry>
    </collision>
  </link>
  <joint
    name="servo_J_gl1"
    type="revolute">
    <origin
      xyz="0 -0.0025679 -0.00031809"
      rpy="0 0 0" />
    <parent
      link="servo" />
    <child
      link="gl1" />
    <axis
      xyz="0 -0.99242 -0.12293" />
    <limit
      lower="0"
      upper="1.3"
      effort="20"
      velocity="1" />
  </joint>
  <link
    name="gl2">
    <inertial>
      <origin
        xyz="0.0152742472160872 0.0009599689001214 -0.00774967381216296"
        rpy="0 0 0" />
      <mass
        value="0.00161819144334082" />
      <inertia
        ixx="6.19798721504658E-08"
        ixy="-1.13290188200474E-08"
        ixz="9.14573383118298E-08"
        iyy="2.49526075826032E-07"
        iyz="6.73897257372591E-09"
        izz="1.95958210314882E-07" />
    </inertial>
    <visual>
      <origin
        xyz="0 0 0"
        rpy="0 0 0" />
      <geometry>
        <mesh
          filename="package://manipulator1/meshes/gl2.STL" />
      </geometry>
      <material
        name="">
        <color
          rgba="1 1 1 0.35" />
      </material>
    </visual>
    <collision>
      <origin
        xyz="0 0 0"
        rpy="0 0 0" />
      <geometry>
        <mesh
          filename="package://manipulator1/meshes/gl2.STL" />
      </geometry>
    </collision>
  </link>
  <joint
    name="gl1_j_gl2"
    type="revolute">
    <origin
      xyz="0.011189 -0.0066954 0.013378"
      rpy="0 0 0" />
    <parent
      link="gl1" />
    <child
      link="gl2" />
    <axis
      xyz="0 -0.99242 -0.12293" />
    <limit
      lower="0"
      upper="1"
      effort="20"
      velocity="1" />
    <mimic 
      joint="servo_J_gl1" 
      multiplier="1.0" 
      offset="0.0" />
  </joint>
  <link
    name="gl3">
    <inertial>
      <origin
        xyz="-0.00688950732976257 0.00271550016503985 -0.0219217940427769"
        rpy="0 0 0" />
      <mass
        value="0.00412427894973239" />
      <inertia
        ixx="2.92803824500752E-06"
        ixy="1.10754930313204E-07"
        ixz="-8.94106655859301E-07"
        iyy="3.18727754562753E-06"
        iyz="3.55124622304955E-07"
        izz="3.64403910334616E-07" />
    </inertial>
    <visual>
      <origin
        xyz="0 0 0"
        rpy="0 0 0" />
      <geometry>
        <mesh
          filename="package://manipulator1/meshes/gl3.STL" />
      </geometry>
      <material
        name="">
        <color
          rgba="1 1 1 0.35" />
      </material>
    </visual>
    <collision>
      <origin
        xyz="0 0 0"
        rpy="0 0 0" />
      <geometry>
        <mesh
          filename="package://manipulator1/meshes/gl3.STL" />
      </geometry>
    </collision>
  </link>
  <joint
    name="gl2_j_gl3"
    type="revolute">
    <origin
      xyz="0.022537 0.010589 -0.032605"
      rpy="0 0 0" />
    <parent
      link="gl2" />
    <child
      link="gl3" />
    <axis
      xyz="0 0.99242 0.12293" />
    <limit
      lower="0"
      upper="1"
      effort="20"
      velocity="1" />
    <mimic 
      joint="servo_J_gl1" 
      multiplier="1.0" 
      offset="0.0" />
  </joint>
  <link
    name="jaw_cover">
    <inertial>
      <origin
        xyz="-0.00650870267338388 0.00276414662962443 -0.0223153366915307"
        rpy="0 0 0" />
      <mass
        value="0.0178205529159882" />
      <inertia
        ixx="1.15040977000637E-05"
        ixy="1.59405989883888E-07"
        ixz="-1.2866760130257E-06"
        iyy="1.22145473216694E-05"
        iyz="1.25853524303917E-06"
        izz="2.21025534276384E-06" />
    </inertial>
    <visual>
      <origin
        xyz="0 0 0"
        rpy="0 0 0" />
      <geometry>
        <mesh
          filename="package://manipulator1/meshes/jaw_cover.STL" />
      </geometry>
      <material
        name="">
        <color
          rgba="1 1 1 0.35" />
      </material>
    </visual>
    <collision>
      <origin
        xyz="0 0 0"
        rpy="0 0 0" />
      <geometry>
        <mesh
          filename="package://manipulator1/meshes/jaw_cover.STL" />
      </geometry>
    </collision>
  </link>
  <joint
    name="gl3_j_jaw_cover"
    type="revolute">   <!-- modification : revolute -> fixed -->
    <origin
      xyz="-0.0046281 0.020142 -0.060918"
      rpy="0 0 0" />
    <parent
      link="gl3" />
    <child
      link="jaw_cover" />
    <axis
      xyz="0 0.99242 0.12293" />
    <limit
      lower="0"
      upper="1"
      effort="20"
      velocity="1" />
    <mimic 
      joint="servo_J_gl1" 
      multiplier="1.0" 
      offset="0.0" />
  </joint>
  <link
    name="jaw1">
    <inertial>
      <origin
        xyz="-0.00286655930693158 0.00295265085958851 -0.0238368047712543"
        rpy="0 0 0" />
      <mass
        value="0.0061353574972217" />
      <inertia
        ixx="2.21237916204447E-06"
        ixy="3.48465115376688E-08"
        ixz="-2.81231499477908E-07"
        iyy="2.48157831604321E-06"
        iyz="2.41849575515697E-07"
        izz="5.59189002996365E-07" />
    </inertial>
    <visual>
      <origin
        xyz="0 0 0"
        rpy="0 0 0" />
      <geometry>
        <mesh
          filename="package://manipulator1/meshes/jaw1.STL" />
      </geometry>
      <material
        name="">
        <color
          rgba="0.784313725490196 0.556862745098039 0.0274509803921569 1" />
      </material>
    </visual>
    <collision>
      <origin
        xyz="0 0 0"
        rpy="0 0 0" />
      <geometry>
        <mesh
          filename="package://manipulator1/meshes/jaw1.STL" />
      </geometry>
    </collision>
  </link>
  <joint
    name="joaw_cover_j_jaw"
    type="fixed">
    <origin
      xyz="-0.013296 -0.0012455 -0.010282"
      rpy="0 0 0" />
    <parent
      link="jaw_cover" />
    <child
      link="jaw1" />
    <axis
      xyz="0 0 0" />
  </joint>
  <link
    name="gl2M">
    <inertial>
      <origin
        xyz="-0.0155641907289482 -0.000886799854665776 0.00715899193136793"
        rpy="0 0 0" />
      <mass
        value="0.00161819144334083" />
      <inertia
        ixx="5.50714146964941E-08"
        ixy="-1.0664180240746E-08"
        ixz="8.6090203890411E-08"
        iyy="2.49630479366597E-07"
        iyz="5.89613966102088E-09"
        izz="2.02762264228293E-07" />
    </inertial>
    <visual>
      <origin
        xyz="0 0 0"
        rpy="0 0 0" />
      <geometry>
        <mesh
          filename="package://manipulator1/meshes/gl2M.STL" />
      </geometry>
      <material
        name="">
        <color
          rgba="1 1 1 0.35" />
      </material>
    </visual>
    <collision>
      <origin
        xyz="0 0 0"
        rpy="0 0 0" />
      <geometry>
        <mesh
          filename="package://manipulator1/meshes/gl2M.STL" />
      </geometry>
    </collision>
  </link>
  <joint
    name="gl1_j_gl2M"
    type="revolute">
    <origin
      xyz="-0.011189 -0.0032287 -0.014608"
      rpy="0 0 0" />
    <parent
      link="gl1" />
    <child
      link="gl2M" />
    <axis
      xyz="0 -0.99242 -0.12293" />
    <limit
      lower="0"
      upper="1"
      effort="20"
      velocity="1" />
    <mimic 
      joint="servo_J_gl1" 
      multiplier="1.0" 
      offset="0.0" />
  </joint>
  <link
    name="gl3M">
    <inertial>
      <origin
        xyz="0.0140099150498048 0.00501570855779621 -0.0404910047136704"
        rpy="0 0 0" />
      <mass
        value="0.00412427894973244" />
      <inertia
        ixx="2.87473095935985E-06"
        ixy="-1.19684662249975E-07"
        ixz="9.6619493885601E-07"
        iyy="3.1880831479486E-06"
        iyz="3.48621124942479E-07"
        izz="4.16905593661381E-07" />
    </inertial>
    <visual>
      <origin
        xyz="0 0 0"
        rpy="0 0 0" />
      <geometry>
        <mesh
          filename="package://manipulator1/meshes/gl3M.STL" />
      </geometry>
      <material
        name="">
        <color
          rgba="1 1 1 0.35" />
      </material>
    </visual>
    <collision>
      <origin
        xyz="0 0 0"
        rpy="0 0 0" />
      <geometry>
        <mesh
          filename="package://manipulator1/meshes/gl3M.STL" />
      </geometry>
    </collision>
  </link>
  <joint
    name="gl2M_j_gl3m"
    type="revolute">
    <origin
      xyz="-0.029033 0.0047965 0.014153"
      rpy="0 0 0" />
    <parent
      link="gl2M" />
    <child
      link="gl3M" />
    <axis
      xyz="0 0.99242 0.12293" />
    <limit
      lower="0"
      upper="1"
      effort="20"
      velocity="1" />

  </joint>
  <link
    name="jaw_cover_2">
    <inertial>
      <origin
        xyz="-0.00849129732663423 0.0027643485644937 -0.0223153116774026"
        rpy="0 0 0" />
      <mass
        value="0.0178205529159885" />
      <inertia
        ixx="1.15040977000644E-05"
        ixy="-1.59361390195458E-07"
        ixz="1.28668153768374E-06"
        iyy="1.221453316311E-05"
        iyz="1.25859151599525E-06"
        izz="2.21026950132292E-06" />
    </inertial>
    <visual>
      <origin
        xyz="0 0 0"
        rpy="0 0 0" />
      <geometry>
        <mesh
          filename="package://manipulator1/meshes/jaw_cover_2.STL" />
      </geometry>
      <material
        name="">
        <color
          rgba="1 1 1 0.35" />
      </material>
    </visual>
    <collision>
      <origin
        xyz="0 0 0"
        rpy="0 0 0" />
      <geometry>
        <mesh
          filename="package://manipulator1/meshes/jaw_cover_2.STL" />
      </geometry>
    </collision>
  </link>
  <joint
    name="gl3M_j_jaw_cover_2"
    type="revolute">  <!-- modification : revolute -> fixed -->
    <origin
      xyz="0.027904 0.022395 -0.079112"
      rpy="0 0 0" />
    <parent
      link="gl3M" />
    <child
      link="jaw_cover_2" />
    <axis
      xyz="0 -0.99242 -0.12293" />
    <limit
      lower="0"
      upper="1"
      effort="20"
      velocity="1" />
    <mimic 
      joint="servo_J_gl1" 
      multiplier="1.0" 
      offset="0.0" />
  </joint>
  <link
    name="jaw2">
    <inertial>
      <origin
        xyz="0.0028665600236728 0.0029527738599946 -0.0238367347486339"
        rpy="0 0 0" />
      <mass
        value="0.00613534362328671" />
      <inertia
        ixx="2.21237061107334E-06"
        ixy="-3.48273075668441E-08"
        ixz="2.812339837702E-07"
        iyy="2.48157400047625E-06"
        iyz="2.41833237314832E-07"
        izz="5.59184961467305E-07" />
    </inertial>
    <visual>
      <origin
        xyz="0 0 0"
        rpy="0 0 0" />
      <geometry>
        <mesh
          filename="package://manipulator1/meshes/jaw2.STL" />
      </geometry>
      <material
        name="">
        <color
          rgba="0.784313725490196 0.556862745098039 0.0274509803921569 1" />
      </material>
    </visual>
    <collision>
      <origin
        xyz="0 0 0"
        rpy="0 0 0" />
      <geometry>
        <mesh
          filename="package://manipulator1/meshes/jaw2.STL" />
      </geometry>
    </collision>
  </link>
  <joint
    name="jaw_cover_j_jaw_cover_2"
    type="fixed">
    <origin
      xyz="-0.0017037 -0.0012455 -0.010282"
      rpy="0 0 0" />
    <parent
      link="jaw_cover_2" />
    <child
      link="jaw2" />
    <axis
      xyz="0 0 0" />
  </joint>
  <link
    name="gl4">
    <inertial>
      <origin
        xyz="-0.00981403529941827 0.00386820322553283 -0.0312273795882327"
        rpy="0 0 0" />
      <mass
        value="0.0032869744029739" />
      <inertia
        ixx="1.47612577642965E-06"
        ixy="5.54340087954537E-08"
        ixz="-4.47509795589427E-07"
        iyy="1.61131149814724E-06"
        iyz="1.78416699628077E-07"
        izz="1.93083175348405E-07" />
    </inertial>
    <visual>
      <origin
        xyz="0 0 0"
        rpy="0 0 0" />
      <geometry>
        <mesh
          filename="package://manipulator1/meshes/gl4.STL" />
      </geometry>
      <material
        name="">
        <color
          rgba="1 1 1 0.35" />
      </material>
    </visual>
    <collision>
      <origin
        xyz="0 0 0"
        rpy="0 0 0" />
      <geometry>
        <mesh
          filename="package://manipulator1/meshes/gl4.STL" />
      </geometry>
    </collision>
  </link>
  <joint
    name="g_mainbody_j_gl4"
    type="revolute">
    <origin
      xyz="0.0432 -0.0060214 -0.05307"
      rpy="0 0 0" />
    <parent
      link="gripper_mainbody" />
    <child
      link="gl4" />
    <axis
      xyz="0 -0.99242 -0.12293" />
    <limit
      lower="0"
      upper="1"
      effort="20"
      velocity="1" />
      
    <mimic 
      joint="servo_J_gl1" 
      multiplier="1.0" 
      offset="0.0" />
  </joint>
  <link
    name="jaw_cover1">
    <inertial>
      <origin
        xyz="-0.00650870267339732 0.00276414662961666 -0.0223153366915287"
        rpy="0 0 0" />
      <mass
        value="0.0178205529159882" />
      <inertia
        ixx="1.15040977000637E-05"
        ixy="1.59405989883888E-07"
        ixz="-1.28667601302571E-06"
        iyy="1.22145473216694E-05"
        iyz="1.25853524303917E-06"
        izz="2.21025534276384E-06" />
    </inertial>
    <visual>
      <origin
        xyz="0 0 0"
        rpy="0 0 0" />
      <geometry>
        <mesh
          filename="package://manipulator1/meshes/jaw_cover1.STL" />
      </geometry>
      <material
        name="">
        <color
          rgba="1 1 1 0.35" />
      </material>
    </visual>
    <collision>
      <origin
        xyz="0 0 0"
        rpy="0 0 0" />
      <geometry>
        <mesh
          filename="package://manipulator1/meshes/jaw_cover1.STL" />
      </geometry>
    </collision>
  </link>
  <joint
    name="gl4_j_jaw_cover1"
    type="revolute">    <!-- modification : revolute -> fixed -->
    <origin
      xyz="-0.019628 0.020142 -0.060918"
      rpy="0 0 0" />
    <parent
      link="gl4" />
    <child
      link="jaw_cover1" />
    <axis
      xyz="0 -0.99242 -0.12293" />
    <limit
      lower="0"
      upper="1"
      effort="20"
      velocity="1" />
      
    <mimic 
      joint="servo_J_gl1" 
      multiplier="1.0" 
      offset="0.0" />
  </joint>
  <link
    name="jaw11">
    <inertial>
      <origin
        xyz="-0.0028665593069318 0.00295265085958873 -0.0238368047712545"
        rpy="0 0 0" />
      <mass
        value="0.0061353574972217" />
      <inertia
        ixx="2.21237916204447E-06"
        ixy="3.48465115376688E-08"
        ixz="-2.81231499477907E-07"
        iyy="2.48157831604321E-06"
        iyz="2.41849575515697E-07"
        izz="5.59189002996364E-07" />
    </inertial>
    <visual>
      <origin
        xyz="0 0 0"
        rpy="0 0 0" />
      <geometry>
        <mesh
          filename="package://manipulator1/meshes/jaw11.STL" />
      </geometry>
      <material
        name="">
        <color
          rgba="0.784313725490196 0.556862745098039 0.0274509803921569 1" />
      </material>
    </visual>
    <collision>
      <origin
        xyz="0 0 0"
        rpy="0 0 0" />
      <geometry>
        <mesh
          filename="package://manipulator1/meshes/jaw11.STL" />
      </geometry>
    </collision>
  </link>
  <joint
    name="jaw_cover1_j_jaw1"
    type="fixed">
    <origin
      xyz="-0.013296 -0.0012455 -0.010282"
      rpy="0 0 0" />
    <parent
      link="jaw_cover1" />
    <child
      link="jaw11" />
    <axis
      xyz="0 0 0" />
  </joint>
  <link
    name="gl4M">
    <inertial>
      <origin
        xyz="0.0107045340669838 0.0038323446599231 -0.0309378991823357"
        rpy="0 0 0" />
      <mass
        value="0.00328697440297392" />
      <inertia
        ixx="1.44944491867369E-06"
        ixy="-5.9903433653792E-08"
        ixz="4.83590740269611E-07"
        iyy="1.61171471059135E-06"
        iyz="1.75161630720812E-07"
        izz="2.19360820660295E-07" />
    </inertial>
    <visual>
      <origin
        xyz="0 0 0"
        rpy="0 0 0" />
      <geometry>
        <mesh
          filename="package://manipulator1/meshes/gl4M.STL" />
      </geometry>
      <material
        name="">
        <color
          rgba="1 1 1 0.35" />
      </material>
    </visual>
    <collision>
      <origin
        xyz="0 0 0"
        rpy="0 0 0" />
      <geometry>
        <mesh
          filename="package://manipulator1/meshes/gl4M.STL" />
      </geometry>
    </collision>
  </link>
  <joint
    name="g_main_body_j_gl4M"
    type="revolute">
    <origin
      xyz="-0.054253 -0.0060214 -0.05307"
      rpy="0 0 0" />
    <parent
      link="gripper_mainbody" />
    <child
      link="gl4M" />
    <axis
      xyz="0 -0.99242 -0.12293" />
    <limit
      lower="0"
      upper="1"
      effort="20"
      velocity="1" />
  </joint>
  <link
    name="jaw_cover2">
    <inertial>
      <origin
        xyz="0.00650870267339276 0.00276434856448904 -0.0223153116774197"
        rpy="0 0 0" />
      <mass
        value="0.0178205529159885" />
      <inertia
        ixx="1.15040977000644E-05"
        ixy="-1.59361390195458E-07"
        ixz="1.28668153768374E-06"
        iyy="1.221453316311E-05"
        iyz="1.25859151599525E-06"
        izz="2.21026950132292E-06" />
    </inertial>
    <visual>
      <origin
        xyz="0 0 0"
        rpy="0 0 0" />
      <geometry>
        <mesh
          filename="package://manipulator1/meshes/jaw_cover2.STL" />
      </geometry>
      <material
        name="">
        <color
          rgba="1 1 1 0.35" />
      </material>
    </visual>
    <collision>
      <origin
        xyz="0 0 0"
        rpy="0 0 0" />
      <geometry>
        <mesh
          filename="package://manipulator1/meshes/jaw_cover2.STL" />
      </geometry>
    </collision>
  </link>
  <joint
    name="gl4M_jaw_cover2"
    type="revolute">    <!-- modification : revolute -> fixed -->
    <origin
      xyz="0.021409 0.02007 -0.060339"
      rpy="0 0 0" />
    <parent
      link="gl4M" />
    <child
      link="jaw_cover2" />
    <axis
      xyz="0 0.99242 0.12293" />
    <limit
      lower="0"
      upper="1"
      effort="20"
      velocity="1" />
    <mimic 
      joint="servo_J_gl1" 
      multiplier="1.0" 
      offset="0.0" />
  </joint>
  <link
    name="jaw22">
    <inertial>
      <origin
        xyz="0.0028665600236728 0.0029527738599946 -0.0238367347486339"
        rpy="0 0 0" />
      <mass
        value="0.00613534362328671" />
      <inertia
        ixx="2.21237061107334E-06"
        ixy="-3.48273075668441E-08"
        ixz="2.812339837702E-07"
        iyy="2.48157400047625E-06"
        iyz="2.41833237314832E-07"
        izz="5.59184961467305E-07" />
    </inertial>
    <visual>
      <origin
        xyz="0 0 0"
        rpy="0 0 0" />
      <geometry>
        <mesh
          filename="package://manipulator1/meshes/jaw22.STL" />
      </geometry>
      <material
        name="">
        <color
          rgba="0.784313725490196 0.556862745098039 0.0274509803921569 1" />
      </material>
    </visual>
    <collision>
      <origin
        xyz="0 0 0"
        rpy="0 0 0" />
      <geometry>
        <mesh
          filename="package://manipulator1/meshes/jaw22.STL" />
      </geometry>
    </collision>
  </link>
  <joint
    name="jaw_cover_j_jaw2"
    type="fixed">
    <origin
      xyz="0.0132963322155747 -0.00124548232917698 -0.0102817691880914"
      rpy="0 0 0" />
    <parent
      link="jaw_cover2" />
    <child
      link="jaw22" />
    <axis
      xyz="0 0 0" />
  </joint>
  <link
    name="link2_side_plate21">
    <inertial>
      <origin
        xyz="4.44089209850063E-16 -0.000621912583298689 0.0311549842986292"
        rpy="0 0 0" />
      <mass
        value="0.0528050348230073" />
      <inertia
        ixx="0.000126324772056132"
        ixy="-3.13440390194027E-21"
        ixz="-6.94412688415756E-20"
        iyy="9.47014380168939E-05"
        iyz="1.25526676510131E-06"
        izz="3.18433550176673E-05" />
    </inertial>
    <visual>
      <origin
        xyz="0 0 0"
        rpy="0 0 0" />
      <geometry>
        <mesh
          filename="package://manipulator1/meshes/link2_side_plate21.STL" />
      </geometry>
      <material
        name="">
        <color
          rgba="0.627450980392157 0.627450980392157 0.627450980392157 1" />
      </material>
    </visual>
    <collision>
      <origin
        xyz="0 0 0"
        rpy="0 0 0" />
      <geometry>
        <mesh
          filename="package://manipulator1/meshes/link2_side_plate21.STL" />
      </geometry>
    </collision>
  </link>
  <joint
    name="end_part_j_side_plate21"
    type="fixed">
    <origin
      xyz="-0.0455 0 0.015927"
      rpy="0 0 0" />
    <parent
      link="link1_end_part" />
    <child
      link="link2_side_plate21" />
    <axis
      xyz="0 0 0" />
  </joint>
  <link
    name="link1_side_plate22">
    <inertial>
      <origin
        xyz="4.44089209850063E-16 4.44089209850063E-16 0.0310582864617436"
        rpy="0 0 0" />
      <mass
        value="0.0499638320857502" />
      <inertia
        ixx="0.00016760074660055"
        ixy="-1.58171503716543E-20"
        ixz="-1.2910550294783E-19"
        iyy="0.000117287241228738"
        iyz="-5.1572738211495E-19"
        izz="5.05216880055024E-05" />
    </inertial>
    <visual>
      <origin
        xyz="0 0 0"
        rpy="0 0 0" />
      <geometry>
        <mesh
          filename="package://manipulator1/meshes/link1_side_plate22.STL" />
      </geometry>
      <material
        name="">
        <color
          rgba="0.627450980392157 0.627450980392157 0.627450980392157 1" />
      </material>
    </visual>
    <collision>
      <origin
        xyz="0 0 0"
        rpy="0 0 0" />
      <geometry>
        <mesh
          filename="package://manipulator1/meshes/link1_side_plate22.STL" />
      </geometry>
    </collision>
  </link>
  <joint
    name="outer_shaft1_j_side_plate22"
    type="fixed">
    <origin
      xyz="-0.047 0 0"
      rpy="0 0 0" />
    <parent
      link="outer_shaft1" />
    <child
      link="link1_side_plate22" />
    <axis
      xyz="0 0 0" />
  </joint>
  <link
    name="link1_side_plate2">
    <inertial>
      <origin
        xyz="0 0.0150134261644275 0.0554613514893126"
        rpy="0 0 0" />
      <mass
        value="0.0682158367067577" />
      <inertia
        ixx="0.000205387282310402"
        ixy="-2.28687018994439E-22"
        ixz="-8.90509245532832E-20"
        iyy="0.000126772358326724"
        iyz="-1.08018754989578E-08"
        izz="7.88991566366222E-05" />
    </inertial>
    <visual>
      <origin
        xyz="0 0 0"
        rpy="0 0 0" />
      <geometry>
        <mesh
          filename="package://manipulator1/meshes/link1_side_plate2.STL" />
      </geometry>
      <material
        name="">
        <color
          rgba="0.627450980392157 0.627450980392157 0.627450980392157 1" />
      </material>
    </visual>
    <collision>
      <origin
        xyz="0 0 0"
        rpy="0 0 0" />
      <geometry>
        <mesh
          filename="package://manipulator1/meshes/link1_side_plate2.STL" />
      </geometry>
    </collision>
  </link>
  <joint
    name="plate_support_j_side_plate2"
    type="fixed">
    <origin
      xyz="-0.0885 0.045 -0.00067857"
      rpy="0 0 0" />
    <parent
      link="plate_support" />
    <child
      link="link1_side_plate2" />
    <axis
      xyz="0 0 0" />
  </joint>
</robot>
