<?xml version="1.0"?>
<robot name="manipulator1">

  <!-- ================= Materials ================= -->
  <material name="gray"><color rgba="0.7 0.7 0.7 1"/></material>
  <material name="dark"><color rgba="0.2 0.2 0.2 1"/></material>

  <!-- ================= Base ================= -->
  <link name="base_link">
    <visual>
      <origin xyz="0 0 0.05"/>
      <geometry>
        <cylinder radius="0.06" length="0.10"/>
      </geometry>
      <material name="dark"/>
    </visual>
  </link>

  <!-- ================= Base rotation ================= -->
  <link name="base_plate">
    <visual>
      <origin xyz="0 0 0.05"/>
      <geometry>
        <cylinder radius="0.05" length="0.10"/>
      </geometry>
      <material name="gray"/>
    </visual>
  </link>

  <joint name="base_link_j_base_plate" type="revolute">
    <parent link="base_link"/>
    <child  link="base_plate"/>
    <origin xyz="0 0 0.10" rpy="0 0 0"/>
    <axis xyz="0 0 1"/>
    <limit lower="-3.14" upper="3.14" effort="50" velocity="2.0"/>
  </joint>

  <!-- ================= Shoulder ================= -->
  <!-- Effective length ≈ 0.50 m -->
  <link name="link1_side_plate12">
    <visual>
      <origin xyz="0.25 0 0" rpy="0 1.5708 0"/>
      <geometry>
        <cylinder radius="0.03" length="0.50"/>
      </geometry>
      <material name="gray"/>
    </visual>
  </link>

  <joint name="side_plate1_j_side_plate12" type="revolute">
    <parent link="base_plate"/>
    <child  link="link1_side_plate12"/>
    <origin xyz="0 0 0" rpy="0 -1.5708 0"/>
    <axis xyz="0 1 0"/>
    <limit lower="-2.4" upper="2.4" effort="40" velocity="2.0"/>
  </joint>

  <!-- ================= Elbow ================= -->
  <!-- Effective length ≈ 0.35 m -->
  <link name="link2_side_plate_12">
    <visual>
      <origin xyz="0.175 0 0" rpy="0 1.5708 0"/>
      <geometry>
        <cylinder radius="0.025" length="0.35"/>
      </geometry>
      <material name="gray"/>
    </visual>
  </link>

  <joint name="motor_holder_j_side_plate_12" type="revolute">
    <parent link="link1_side_plate12"/>
    <child  link="link2_side_plate_12"/>
    <origin xyz="0.50 0 0" rpy="0 1.5708 0"/>
    <axis xyz="0 1 0"/>
    <limit lower="-2.4" upper="2.4" effort="40" velocity="2.0"/>
  </joint>

    <!-- ================= Wrist Roll (ZERO LENGTH) ================= -->
  <link name="bevel1">
    <!-- purely a frame holder, no physical length -->
    <visual>
      <origin xyz="0 0 0"/>
      <geometry>
        <sphere radius="0.01"/>
      </geometry>
      <material name="gray"/>
    </visual>
  </link>

  <joint name="link3_j_bevel1" type="revolute">
    <parent link="link2_side_plate_12"/>
    <child  link="bevel1"/>

    <!-- wrist center = exactly at end of link2 -->
    <origin xyz="0.35 0 0" rpy="0 0 0"/>

    <!-- roll -->
    <axis xyz="1 0 0"/>
    <limit lower="-3.14" upper="3.14" effort="20" velocity="3.0"/>
  </joint>

  <!-- ================= Wrist Pitch (SAME LOCATION) ================= -->
  <link name="bevel3">
    <!-- also zero-length frame -->
    <visual>
      <origin xyz="0 0 0"/>
      <geometry>
        <sphere radius="0.012"/>
      </geometry>
      <material name="dark"/>
    </visual>
  </link>

  <joint name="bevel_coupler_j_bevel3" type="revolute">
    <parent link="bevel1"/>
    <child  link="bevel3"/>

    <!-- SAME ORIGIN as previous joint -->
    <origin xyz="0 0 0" rpy="0 0 0"/>

    <!-- pitch -->
    <axis xyz="0 1 0"/>
    <limit lower="-2.4" upper="2.4" effort="20" velocity="3.0"/>
  </joint>

  <!-- ================= Tool Rotor ================= -->
  <link name="gl1">
    <visual>
      <origin xyz="0.03 0 0" rpy="0 1.5708 0"/>
      <geometry>
        <cylinder radius="0.015" length="0.06"/>
      </geometry>
      <material name="dark"/>
    </visual>
  </link>

  <joint name="servo_J_gl1" type="revolute">
    <parent link="bevel3"/>
    <child  link="gl1"/>

    <!-- small tool offset -->
    <origin xyz="0.06 0 0" rpy="0 0 0"/>

    <!-- claw rotor -->
    <axis xyz="0 0 1"/>
    <limit lower="0.0" upper="1.3" effort="10" velocity="3.0"/>
  </joint>

</robot>
  
  
  
  
  
  
  
  
  
  
  
  
  
  
  
  
  
  
  
  
  
  
  
  
  
  
  
  
  
  
  
  
  
  
  
  
  